[2024-05-22 14:53:41,468] 1707 asyncio - ERROR - Task exception was never retrieved
future: <Task finished name='Task-34' coro=<WebSocketProtocol13.write_message.<locals>.wrapper() done, defined at C:\Users\karan\OneDrive\Documents\Code\Gen_AI_Projects\mcqgen\env\lib\site-packages\tornado\websocket.py:1085> exception=WebSocketClosedError()>
Traceback (most recent call last):
  File "C:\Users\karan\OneDrive\Documents\Code\Gen_AI_Projects\mcqgen\env\lib\site-packages\tornado\websocket.py", line 1087, in wrapper
    await fut
tornado.iostream.StreamClosedError: Stream is closed

During handling of the above exception, another exception occurred:

Traceback (most recent call last):
  File "C:\Users\karan\OneDrive\Documents\Code\Gen_AI_Projects\mcqgen\env\lib\site-packages\tornado\websocket.py", line 1089, in wrapper
    raise WebSocketClosedError()
tornado.websocket.WebSocketClosedError
